2025-06-24 18:22:53,365 [INFO] main: ðŸš€  ETL pipeline started
2025-06-24 18:22:53,365 [WARNING] main: Overwriting existing synthetic folder /home/anr/apps/AlethiOmics/raw_data
2025-06-24 18:22:53,365 [INFO] main: ðŸ§ª  Running synthetic generator: /opt/anaconda3/envs/alethiomics/bin/python3.10 -m etl.utils.synthetic_data_generator --num_experiments 8 --seed 20250624 --out_dir raw_data/synthetic_runs
2025-06-24 18:22:53,761 [ERROR] main: Synthetic generator failed (exit 2)
2025-06-24 18:22:53,762 [ERROR] main: STDOUT:

2025-06-24 18:22:53,762 [ERROR] main: STDERR:
/opt/anaconda3/envs/alethiomics/lib/python3.10/runpy.py:126: RuntimeWarning: 'etl.utils.synthetic_data_generator' found in sys.modules after import of package 'etl.utils', but prior to execution of 'etl.utils.synthetic_data_generator'; this may result in unpredictable behaviour
  warn(RuntimeWarning(msg))
usage: synthetic_data_generator.py [-h] [-n NUM_EXPERIMENTS] [--seed SEED]
                                   out_dir
synthetic_data_generator.py: error: unrecognized arguments: --out_dir

